Workbook

Sheet SCI_Report#BL68LX#jwade#25-MAR-
A1: Plan Status | B1: Origin | C1: Origin City | D1: Origin State | E1: Destination | F1: Destination City | G1: Destination State | H1: Distance | I1: Planned Departure Date | J1: Planned Arrival End | K1: Equipment | L1: Weight | M1: Mode | N1: Carrier | O1: SCAC | P1: Price | Q1: Carrier Ref./Conf. # | R1: Created Date | S1: Description | T1: Class Code | U1: Quantity | V1: Pickup Appointment Date | W1: Ship Month | X1: Weight Num | Y1: Distance Num
A2: Covered | B2: BlueLinx Corporation | C2: Tampa | D2: FL | E2: TIBBETTS-PENSACOLA, LMC 408600 | F2: PENSACOLA | G2: FL | H2: 425 mi | I2: 15-Oct-25 12:01 AM EDT | J2: 15-Oct-25 11:59 PM CDT | K2: Dry Van | L2: 702 lb | M2: LTL | N2: Southeastern Freight | O2: SEFL | P2: 135.91 | Q2: 446799131 | R2: 14-Oct-25 2:26 PM EDT | S2: 1 palletized - boxes of sealant | T2: 65 | U2: 1 ea | V2: 15-Oct-25 1:53 PM EDT | W2: =IF(I2="","",DATE(2000+MID(I2,8,2),MATCH(MID(I2,4,3),{"Jan","Feb","Mar","Apr","May","Jun","Jul","Aug","Sep","Oct","Nov","Dec"},0),1)) -> 45931 | X2: =IF(L2="","",SUBSTITUTE(SUBSTITUTE(L2,",","")," lb",""))*1 -> 702 | Y2: =IF(H2="","",SUBSTITUTE(SUBSTITUTE(H2,",","")," mi",""))*1 -> 425
A3: Covered | B3: TAMLYN & SONS, INC. 20300 | C3: STAFFORD | D3: TX | E3: IMPORT AND EXPORT SOLUTIONS | F3: DEERFIELD BEACH | G3: FL | H3: 1,155 mi | I3: 30-Jan-26 12:01 AM CST | J3: 30-Jan-26 11:59 PM EST | K3: Dry Van | L3: 10 lb | M3: LTL | N3: ESTES EXPRESS LINES | O3: EXLA | P3: 168.92 | Q3: 1560724452 | R3: 29-Jan-26 12:16 PM EST | S3: 10 ft Moulding | T3: 65 | U3: 1 ea | V3: 30-Jan-26 1:51 PM CST | W3: =IF(I3="","",DATE(2000+MID(I3,8,2),MATCH(MID(I3,4,3),{"Jan","Feb","Mar","Apr","May","Jun","Jul","Aug","Sep","Oct","Nov","Dec"},0),1)) -> 46023 | X3: =IF(L3="","",SUBSTITUTE(SUBSTITUTE(L3,",","")," lb",""))*1 -> 10 | Y3: =IF(H3="","",SUBSTITUTE(SUBSTITUTE(H3,",","")," mi",""))*1 -> 1155
A4: Covered | B4: TAPCO COMPANIES | C4: MEADVILLE | D4: PA | E4: BLUELINX CHICAGO | F4: UNIVERSITY PARK | G4: IL | H4: 420 mi | I4: 27-Jan-26 12:01 AM EST | J4: 28-Jan-26 11:59 PM CST | K4: Dry Van | L4: 7,403 lb | M4: LTL | N4: ESTES EXPRESS LINES | O4: EXLA | P4: 603.78 | R4: 23-Jan-26 2:41 PM EST | S4: 100 in x 20 in x 24 in - jack posts | T4: 65 | U4: 10 ea | W4: =IF(I4="","",DATE(2000+MID(I4,8,2),MATCH(MID(I4,4,3),{"Jan","Feb","Mar","Apr","May","Jun","Jul","Aug","Sep","Oct","Nov","Dec"},0),1)) -> 46023 | X4: =IF(L4="","",SUBSTITUTE(SUBSTITUTE(L4,",","")," lb",""))*1 -> 7403 | Y4: =IF(H4="","",SUBSTITUTE(SUBSTITUTE(H4,",","")," mi",""))*1 -> 420
A5: Covered | B5: ALL VAN | C5: LAVERGNE | D5: TN | E5: BLUELINX BELLINGHAM | F5: BELLINGHAM | G5: MA | H5: 1,068 mi | I5: 06-Mar-26 8:00 AM CST | J5: 10-Mar-26 5:00 PM EDT | K5: Dry Van | L5: 51 lb | M5: LTL | N5: ESTES EXPRESS LINES | O5: EXLA | P5: 172.23 | Q5: 373672404 | R5: 05-Mar-26 3:10 PM EST | S5: 108 in x 10 x 4 - curtainside accessories - palletized | T5: 65 | U5: 2 ea | V5: 06-Mar-26 1:15 AM CST | W5: =IF(I5="","",DATE(2000+MID(I5,8,2),MATCH(MID(I5,4,3),{"Jan","Feb","Mar","Apr","May","Jun","Jul","Aug","Sep","Oct","Nov","Dec"},0),1)) -> 46082 | X5: =IF(L5="","",SUBSTITUTE(SUBSTITUTE(L5,",","")," lb",""))*1 -> 51 | Y5: =IF(H5="","",SUBSTITUTE(SUBSTITUTE(H5,",","")," mi",""))*1 -> 1068
A6: Covered | B6: ROYAL MOULDING LTD-BRISTOL T2 | C6: BRISTOL | D6: TN | E6: GUY C LEE B/M KITTY HAWK | F6: KITTY HAWK | G6: NC | H6: 441 mi | I6: 24-Feb-26 12:01 AM EST | J6: 25-Feb-26 11:59 PM EST | K6: Dry Van | L6: 1,709.06 lb | M6: LTL | N6: ESTES EXPRESS LINES | O6: EXLA | P6: 326.67 | Q6: 391422143 | R6: 20-Feb-26 9:11 AM EST | S6: 10ft - 12ft - Moulding units | T6: 65 | U6: 2 ea | V6: 24-Feb-26 1:36 PM EST | W6: =IF(I6="","",DATE(2000+MID(I6,8,2),MATCH(MID(I6,4,3),{"Jan","Feb","Mar","Apr","May","Jun","Jul","Aug","Sep","Oct","Nov","Dec"},0),1)) -> 46054 | X6: =IF(L6="","",SUBSTITUTE(SUBSTITUTE(L6,",","")," lb",""))*1 -> 1709.06 | Y6: =IF(H6="","",SUBSTITUTE(SUBSTITUTE(H6,",","")," mi",""))*1 -> 441
A7: Covered | B7: BLUELINX CHICAGO | C7: UNIVERSITY PARK | D7: IL | E7: BLUELINX FREDERICK | F7: FREDERICK | G7: MD | H7: 634 mi | I7: 21-Jan-26 12:01 AM CST | J7: 22-Jan-26 11:59 PM EST | K7: Dry Van | L7: 493.27 lb | M7: LTL | N7: ESTES EXPRESS LINES | O7: EXLA | P7: 203.68 | Q7: 1080257086 | R7: 16-Jan-26 5:51 PM EST | S7: 10ft decking accessories | T7: 65 | U7: 1 ea | V7: 21-Jan-26 8:45 AM CST | W7: =IF(I7="","",DATE(2000+MID(I7,8,2),MATCH(MID(I7,4,3),{"Jan","Feb","Mar","Apr","May","Jun","Jul","Aug","Sep","Oct","Nov","Dec"},0),1)) -> 46023 | X7: =IF(L7="","",SUBSTITUTE(SUBSTITUTE(L7,",","")," lb",""))*1 -> 493.27 | Y7: =IF(H7="","",SUBSTITUTE(SUBSTITUTE(H7,",","")," mi",""))*1 -> 634
A8: Covered | B8: L&L STRUCTURAL STEEL INC | C8: MIAMI | D8: FL | E8: BLUELINX - JACKSONVILLE | F8: YULEE | G8: FL | H8: 364 mi | I8: 09-Feb-26 12:01 AM EST | J8: 09-Feb-26 11:59 PM EST | K8: Dry Van | L8: 2,801.23 lb | M8: LTL | N8: ESTES EXPRESS LINES | O8: EXLA | P8: 416.98 | R8: 06-Feb-26 5:46 PM EST | S8: 10ft track system - accessories - palletized | T8: 65 | U8: 1 ea | W8: =IF(I8="","",DATE(2000+MID(I8,8,2),MATCH(MID(I8,4,3),{"Jan","Feb","Mar","Apr","May","Jun","Jul","Aug","Sep","Oct","Nov","Dec"},0),1)) -> 46054 | X8: =IF(L8="","",SUBSTITUTE(SUBSTITUTE(L8,",","")," lb",""))*1 -> 2801.23 | Y8: =IF(H8="","",SUBSTITUTE(SUBSTITUTE(H8,",","")," mi",""))*1 -> 364
A9: Covered | B9: ALL VAN | C9: LAVERGNE | D9: TN | E9: BLUELINX - GULFPORT | F9: GULFPORT | G9: MS | H9: 492 mi | I9: 09-Feb-26 8:00 AM CST | J9: 10-Feb-26 5:00 PM CST | K9: Dry Van | L9: 299 lb | M9: LTL | N9: ESTES EXPRESS LINES | O9: EXLA | P9: 206 | Q9: 373565547 | R9: 06-Feb-26 4:25 PM EST | S9: 111 in x52 in x 6 in - curtainside accessories | T9: 65 | U9: 1 ea | V9: 09-Feb-26 2:43 PM CST | W9: =IF(I9="","",DATE(2000+MID(I9,8,2),MATCH(MID(I9,4,3),{"Jan","Feb","Mar","Apr","May","Jun","Jul","Aug","Sep","Oct","Nov","Dec"},0),1)) -> 46054 | X9: =IF(L9="","",SUBSTITUTE(SUBSTITUTE(L9,",","")," lb",""))*1 -> 299 | Y9: =IF(H9="","",SUBSTITUTE(SUBSTITUTE(H9,",","")," mi",""))*1 -> 492
A10: Covered | B10: ALL VAN | C10: LAVERGNE | D10: TN | E10: BLUELINX PORTLAND | F10: PORTLAND | G10: ME | H10: 1,181 mi | I10: 09-Feb-26 8:00 AM CST | J10: 10-Feb-26 5:00 PM EST | K10: Dry Van | L10: 30 lb | M10: LTL | N10: ESTES EXPRESS LINES | O10: EXLA | P10: 169.87 | Q10: 373629515 | R10: 06-Feb-26 4:22 PM EST | S10: 111 in x52 in x 6i n - curtainside accessories | T10: 65 | U10: 1 ea | V10: 09-Feb-26 2:43 PM CST | W10: =IF(I10="","",DATE(2000+MID(I10,8,2),MATCH(MID(I10,4,3),{"Jan","Feb","Mar","Apr","May","Jun","Jul","Aug","Sep","Oct","Nov","Dec"},0),1)) -> 46054 | X10: =IF(L10="","",SUBSTITUTE(SUBSTITUTE(L10,",","")," lb",""))*1 -> 30 | Y10: =IF(H10="","",SUBSTITUTE(SUBSTITUTE(H10,",","")," mi",""))*1 -> 1181
A11: Covered | B11: Allvan USA, LLC | C11: La Vergne | D11: TN | E11: BLUELINX - RICHMOND | F11: RICHMOND | G11: VA | H11: 587 mi | I11: 08-Oct-25 8:00 AM CDT | J11: 10-Oct-25 5:00 PM EDT | K11: Dry Van | L11: 50 lb | M11: LTL | N11: ESTES EXPRESS LINES | O11: EXLA | P11: 171 | Q11: 373559269 | R11: 07-Oct-25 1:24 PM EDT | S11: 112 in long curtain van accessory palletized | T11: 65 | U11: 1 ea | V11: 08-Oct-25 1:56 PM CDT | W11: =IF(I11="","",DATE(2000+MID(I11,8,2),MATCH(MID(I11,4,3),{"Jan","Feb","Mar","Apr","May","Jun","Jul","Aug","Sep","Oct","Nov","Dec"},0),1)) -> 45931 | X11: =IF(L11="","",SUBSTITUTE(SUBSTITUTE(L11,",","")," lb",""))*1 -> 50 | Y11: =IF(H11="","",SUBSTITUTE(SUBSTITUTE(H11,",","")," mi",""))*1 -> 587
A12: Covered | B12: Allvan USA, LLC | C12: La Vergne | D12: TN | E12: BLUELINX OMAHA | F12: OMAHA | G12: NE | H12: 744 mi | I12: 17-Feb-26 8:00 AM CST | J12: 19-Feb-26 5:00 PM CST | K12: Dry Van | L12: 22 lb | M12: LTL | N12: ESTES EXPRESS LINES | O12: EXLA | P12: 189.97 | Q12: 373750553 | R12: 16-Feb-26 4:43 PM EST | S12: 114 in x 8 in x 4in - curtain van accessories | T12: 65 | U12: 1 ea | V12: 18-Feb-26 11:40 AM CST | W12: =IF(I12="","",DATE(2000+MID(I12,8,2),MATCH(MID(I12,4,3),{"Jan","Feb","Mar","Apr","May","Jun","Jul","Aug","Sep","Oct","Nov","Dec"},0),1)) -> 46054 | X12: =IF(L12="","",SUBSTITUTE(SUBSTITUTE(L12,",","")," lb",""))*1 -> 22 | Y12: =IF(H12="","",SUBSTITUTE(SUBSTITUTE(H12,",","")," mi",""))*1 -> 744
A13: Covered | B13: ALL VAN | C13: LAVERGNE | D13: TN | E13: BLUELINX GRAND RAPIDS-BUCHANAN | F13: GRAND RAPIDS | G13: MI | H13: 536 mi | I13: 17-Mar-26 8:00 AM CDT | J13: 19-Mar-26 5:00 PM EDT | K13: Dry Van | L13: 884 lb | M13: LTL | N13: ESTES EXPRESS LINES | O13: EXLA | P13: 288.68 | R13: 16-Mar-26 12:22 PM EDT | S13: 119 in x45 in x 30 in curtain van accessories | T13: 65 | U13: 1 ea | W13: =IF(I13="","",DATE(2000+MID(I13,8,2),MATCH(MID(I13,4,3),{"Jan","Feb","Mar","Apr","May","Jun","Jul","Aug","Sep","Oct","Nov","Dec"},0),1)) -> 46082 | X13: =IF(L13="","",SUBSTITUTE(SUBSTITUTE(L13,",","")," lb",""))*1 -> 884 | Y13: =IF(H13="","",SUBSTITUTE(SUBSTITUTE(H13,",","")," mi",""))*1 -> 536
A14: Covered | B14: TREE ISLAND | C14: SAN BERNARDINO | D14: CA | E14: LOWES #1443 HENDERSON FDC | F14: HENDERSON | G14: CO | H14: 986 mi | I14: 26-Jan-26 12:01 AM PST | J14: 28-Jan-26 11:59 PM MST | K14: Dry Van | L14: 1,596.4 lb | M14: LTL | N14: ESTES EXPRESS LINES | O14: EXLA | P14: 426.67 | Q14: 2340631520 | R14: 16-Jan-26 1:26 PM EST | S14: 122 in x 37 in x 25 in - moulding-framing accessories | T14: 65 | U14: 1 ea | V14: 27-Jan-26 8:50 AM PST | W14: =IF(I14="","",DATE(2000+MID(I14,8,2),MATCH(MID(I14,4,3),{"Jan","Feb","Mar","Apr","May","Jun","Jul","Aug","Sep","Oct","Nov","Dec"},0),1)) -> 46023 | X14: =IF(L14="","",SUBSTITUTE(SUBSTITUTE(L14,",","")," lb",""))*1 -> 1596.4 | Y14: =IF(H14="","",SUBSTITUTE(SUBSTITUTE(H14,",","")," mi",""))*1 -> 986
A15: Covered | B15: ALL VAN | C15: LAVERGNE | D15: TN | E15: BLUELINX INDIANAPOLIS | F15: TIPTON | G15: IN | H15: 341 mi | I15: 03-Nov-25 8:00 AM CST | J15: 04-Nov-25 5:00 PM EST | K15: Dry Van | L15: 146 lb | M15: LTL | N15: ESTES EXPRESS LINES | O15: EXLA | P15: 170.49 | Q15: 373629512 | R15: 03-Nov-25 8:30 AM EST | S15: 123 in x25 n x 9in palletized curtainside van accessories | T15: 65 | U15: 1 ea | V15: 03-Nov-25 11:33 AM CST | W15: =IF(I15="","",DATE(2000+MID(I15,8,2),MATCH(MID(I15,4,3),{"Jan","Feb","Mar","Apr","May","Jun","Jul","Aug","Sep","Oct","Nov","Dec"},0),1)) -> 45962 | X15: =IF(L15="","",SUBSTITUTE(SUBSTITUTE(L15,",","")," lb",""))*1 -> 146 | Y15: =IF(H15="","",SUBSTITUTE(SUBSTITUTE(H15,",","")," mi",""))*1 -> 341
A16: Covered | B16: BLUELINX ELKHART | C16: ELKHART | D16: IN | E16: BLUELINX SEATTLE | F16: KENT | G16: WA | H16: 2,109 mi | I16: 26-Feb-26 12:01 AM EST | J16: 26-Feb-26 11:59 PM PST | K16: Dry Van | L16: 2,771.21 lb | M16: LTL | N16: ESTES EXPRESS LINES | O16: EXLA | P16: 918.68 | R16: 25-Feb-26 11:01 AM EST | S16: 12ft j-channel palletized | T16: 65 | U16: 2 ea | W16: =IF(I16="","",DATE(2000+MID(I16,8,2),MATCH(MID(I16,4,3),{"Jan","Feb","Mar","Apr","May","Jun","Jul","Aug","Sep","Oct","Nov","Dec"},0),1)) -> 46054 | X16: =IF(L16="","",SUBSTITUTE(SUBSTITUTE(L16,",","")," lb",""))*1 -> 2771.21 | Y16: =IF(H16="","",SUBSTITUTE(SUBSTITUTE(H16,",","")," mi",""))*1 -> 2109
A17: Covered | B17: BLUELINX CHARLESTON | C17: CHARLESTON | D17: SC | E17: BLUELINX RICHMOND | F17: RICHMOND | G17: VA | H17: 398 mi | I17: 21-Nov-25 12:01 AM EST | J17: 26-Nov-25 11:59 PM EST | K17: Dry Van | L17: 1,900.8 lb | M17: LTL | N17: ESTES EXPRESS LINES | O17: EXLA | P17: 289.46 | R17: 20-Nov-25 9:51 AM EST | S17: 12ft Trim board | T17: 65 | U17: 1 ea | W17: =IF(I17="","",DATE(2000+MID(I17,8,2),MATCH(MID(I17,4,3),{"Jan","Feb","Mar","Apr","May","Jun","Jul","Aug","Sep","Oct","Nov","Dec"},0),1)) -> 45962 | X17: =IF(L17="","",SUBSTITUTE(SUBSTITUTE(L17,",","")," lb",""))*1 -> 1900.8 | Y17: =IF(H17="","",SUBSTITUTE(SUBSTITUTE(H17,",","")," mi",""))*1 -> 398
A18: Covered | B18: BlueLinx Corporation | C18: BROOKLYN PARK | D18: MN | E18: BLOEDORNS LBM #3081 GILLETTE | F18: Lewistown | G18: MT | H18: 855 mi | I18: 09-Jan-26 12:01 AM CST | J18: 12-Jan-26 11:59 PM MST | K18: Dry Van | L18: 266.65 lb | M18: LTL | N18: ESTES EXPRESS LINES | O18: EXLA | P18: 207.46 | Q18: 1381707083 | R18: 07-Jan-26 5:21 PM EST | S18: 12ft Trim board | T18: 65 | U18: 1 ea | V18: 09-Jan-26 12:29 PM CST | W18: =IF(I18="","",DATE(2000+MID(I18,8,2),MATCH(MID(I18,4,3),{"Jan","Feb","Mar","Apr","May","Jun","Jul","Aug","Sep","Oct","Nov","Dec"},0),1)) -> 46023 | X18: =IF(L18="","",SUBSTITUTE(SUBSTITUTE(L18,",","")," lb",""))*1 -> 266.65 | Y18: =IF(H18="","",SUBSTITUTE(SUBSTITUTE(H18,",","")," mi",""))*1 -> 855
A19: Covered | B19: BlueLinx Corporation | C19: BROOKLYN PARK | D19: MN | E19: LOWES #2533 BISMARCK | F19: BISMARCK | G19: ND | H19: 418 mi | I19: 17-Mar-26 12:01 AM CDT | J19: 23-Mar-26 11:59 PM CDT | K19: Dry Van | L19: 469.25 lb | M19: LTL | N19: ESTES EXPRESS LINES | O19: EXLA | P19: 215.39 | Q19: 1381688655 | R19: 10-Mar-26 9:36 AM EDT | S19: 12ft trim-siding accessories - palletized | T19: 65 | U19: 1 ea | V19: 17-Mar-26 10:48 AM CDT | W19: =IF(I19="","",DATE(2000+MID(I19,8,2),MATCH(MID(I19,4,3),{"Jan","Feb","Mar","Apr","May","Jun","Jul","Aug","Sep","Oct","Nov","Dec"},0),1)) -> 46082 | X19: =IF(L19="","",SUBSTITUTE(SUBSTITUTE(L19,",","")," lb",""))*1 -> 469.25 | Y19: =IF(H19="","",SUBSTITUTE(SUBSTITUTE(H19,",","")," mi",""))*1 -> 418
A20: Covered | B20: BLUELINX CINCINNATI | C20: INDEPENDENCE | D20: KY | E20: BLUELINX FORT WORTH | F20: FT WORTH | G20: TX | H20: 952 mi | I20: 19-Feb-26 12:01 AM EST | J20: 20-Feb-26 11:59 PM CST | K20: Dry Van | L20: 1,344 lb | M20: LTL | N20: ESTES EXPRESS LINES | O20: EXLA | P20: 288.01 | Q20: 622503766 | R20: 18-Feb-26 3:01 PM EST | S20: 24 in ground master posts - palletized | T20: 65 | U20: 2 ea | V20: 19-Feb-26 12:45 PM EST | W20: =IF(I20="","",DATE(2000+MID(I20,8,2),MATCH(MID(I20,4,3),{"Jan","Feb","Mar","Apr","May","Jun","Jul","Aug","Sep","Oct","Nov","Dec"},0),1)) -> 46054 | X20: =IF(L20="","",SUBSTITUTE(SUBSTITUTE(L20,",","")," lb",""))*1 -> 1344 | Y20: =IF(H20="","",SUBSTITUTE(SUBSTITUTE(H20,",","")," mi",""))*1 -> 952
A21: Covered | B21: CEDAR CREEK IND | C21: TIPTON | D21: IN | E21: BLUELINX NASHVILLE | F21: MADISON | G21: TN | H21: 319 mi | I21: 06-Mar-26 12:01 AM EST | J21: 06-Mar-26 11:59 PM CST | K21: Dry Van | L21: 10,393.6 lb | M21: LTL | N21: ESTES EXPRESS LINES | O21: EXLA | P21: 752.86 | Q21: 1180225268 | R21: 05-Mar-26 3:16 PM EST | S21: 2x2x8ft Fir strips - palletized | T21: 65 | U21: 4 ea | V21: 09-Mar-26 2:45 PM EDT | W21: =IF(I21="","",DATE(2000+MID(I21,8,2),MATCH(MID(I21,4,3),{"Jan","Feb","Mar","Apr","May","Jun","Jul","Aug","Sep","Oct","Nov","Dec"},0),1)) -> 46082 | X21: =IF(L21="","",SUBSTITUTE(SUBSTITUTE(L21,",","")," lb",""))*1 -> 10393.6 | Y21: =IF(H21="","",SUBSTITUTE(SUBSTITUTE(H21,",","")," mi",""))*1 -> 319
A22: Covered | B22: KITCHEN KOMPACT INC | C22: JEFFERSONVILLE | D22: IN | E22: PRO DESK LOWES #2301 | F22: CHICAGO | G22: IL | H22: 291 mi | I22: 27-Jan-26 12:01 AM EST | J22: 29-Jan-26 11:59 PM CST | K22: Dry Van | L22: 48 lb | M22: LTL | N22: ESTES EXPRESS LINES | O22: EXLA | P22: 129.26 | Q22: 862212793 | R22: 26-Jan-26 9:21 AM EST | S22: 33 in x 30 in x 12 in - cabinet accessories | T22: 65 | U22: 1 ea | V22: 28-Jan-26 1:44 PM EST | W22: =IF(I22="","",DATE(2000+MID(I22,8,2),MATCH(MID(I22,4,3),{"Jan","Feb","Mar","Apr","May","Jun","Jul","Aug","Sep","Oct","Nov","Dec"},0),1)) -> 46023 | X22: =IF(L22="","",SUBSTITUTE(SUBSTITUTE(L22,",","")," lb",""))*1 -> 48 | Y22: =IF(H22="","",SUBSTITUTE(SUBSTITUTE(H22,",","")," mi",""))*1 -> 291
A23: Covered | B23: ROYAL MOULDING LTD-BRISTOL T2 | C23: BRISTOL | D23: TN | E23: GUY C LEE B/M KITTY HAWK | F23: KITTY HAWK | G23: NC | H23: 441 mi | I23: 22-Jan-26 12:01 AM EST | J23: 27-Jan-26 11:59 PM EST | K23: Dry Van | L23: 2,976 lb | M23: LTL | N23: ESTES EXPRESS LINES | O23: EXLA | P23: 353.71 | R23: 20-Jan-26 5:01 PM EST | S23: 4' x 10 ' PVC sheets - palletized | T23: 65 | U23: 4 ea | W23: =IF(I23="","",DATE(2000+MID(I23,8,2),MATCH(MID(I23,4,3),{"Jan","Feb","Mar","Apr","May","Jun","Jul","Aug","Sep","Oct","Nov","Dec"},0),1)) -> 46023 | X23: =IF(L23="","",SUBSTITUTE(SUBSTITUTE(L23,",","")," lb",""))*1 -> 2976 | Y23: =IF(H23="","",SUBSTITUTE(SUBSTITUTE(H23,",","")," mi",""))*1 -> 441
A24: Covered | B24: BLUELINX CHARLOTTE | C24: CHARLOTTE | D24: NC | E24: BLUELINX SAINT LOUIS | F24: BRIDGETON | G24: MO | H24: 718 mi | I24: 10-Dec-25 12:01 AM EST | J24: 15-Dec-25 11:59 PM CST | K24: Dry Van | L24: 163.9 lb | M24: LTL | N24: ESTES EXPRESS LINES | O24: EXLA | P24: 129.87 | Q24: 107955066 | R24: 09-Dec-25 11:11 AM EST | S24: 42 in x 48 in pallet - Vinyl Shrouds | T24: 65 | U24: 1 ea | V24: 10-Dec-25 4:35 PM EST | W24: =IF(I24="","",DATE(2000+MID(I24,8,2),MATCH(MID(I24,4,3),{"Jan","Feb","Mar","Apr","May","Jun","Jul","Aug","Sep","Oct","Nov","Dec"},0),1)) -> 45992 | X24: =IF(L24="","",SUBSTITUTE(SUBSTITUTE(L24,",","")," lb",""))*1 -> 163.9 | Y24: =IF(H24="","",SUBSTITUTE(SUBSTITUTE(H24,",","")," mi",""))*1 -> 718
A25: Covered | B25: ANTHONY OAK FLOORING | C25: MAGNOLIA | D25: AR | E25: RUSSELL-MOORE LUMBER, INC9758 | F25: MONROE | G25: LA | H25: 118 mi | I25: 26-Mar-26 12:01 AM CDT | J25: 27-Mar-26 11:59 PM CDT | K25: Dry Van | L25: 2,276.82 lb | M25: LTL | N25: ESTES EXPRESS LINES | O25: EXLA | P25: 211.04 | R25: 24-Mar-26 12:31 PM EDT | S25: 42â€ wide x 30â€ tall X 90â€ long Red Oak flooring | T25: 65 | U25: 1 ea | W25: =IF(I25="","",DATE(2000+MID(I25,8,2),MATCH(MID(I25,4,3),{"Jan","Feb","Mar","Apr","May","Jun","Jul","Aug","Sep","Oct","Nov","Dec"},0),1)) -> 46082 | X25: =IF(L25="","",SUBSTITUTE(SUBSTITUTE(L25,",","")," lb",""))*1 -> 2276.82 | Y25: =IF(H25="","",SUBSTITUTE(SUBSTITUTE(H25,",","")," mi",""))*1 -> 118
A26: Covered | B26: KITCHEN KOMPACT INC | C26: JEFFERSONVILLE | D26: IN | E26: PRO DESK HOME DEPOT #2001 | F26: MERRILLVILLE | G26: IN | H26: 255 mi | I26: 23-Feb-26 12:01 AM EST | J26: 24-Feb-26 11:59 PM CST | K26: Dry Van | L26: 68 lb | M26: LTL | N26: ESTES EXPRESS LINES | O26: EXLA | P26: 131.72 | Q26: 862251524 | R26: 19-Feb-26 9:31 AM EST | S26: 44 in W x 44 in L x 30 in H - cabinet - palletized | T26: 65 | U26: 1 ea | V26: 23-Feb-26 12:19 PM EST | W26: =IF(I26="","",DATE(2000+MID(I26,8,2),MATCH(MID(I26,4,3),{"Jan","Feb","Mar","Apr","May","Jun","Jul","Aug","Sep","Oct","Nov","Dec"},0),1)) -> 46054 | X26: =IF(L26="","",SUBSTITUTE(SUBSTITUTE(L26,",","")," lb",""))*1 -> 68 | Y26: =IF(H26="","",SUBSTITUTE(SUBSTITUTE(H26,",","")," mi",""))*1 -> 255
A27: Covered | B27: KITCHEN KOMPACT INC | C27: JEFFERSONVILLE | D27: IN | E27: PRO DESK HOME DEPOT #6923 | F27: SOUTH ELGIN | G27: IL | H27: 329 mi | I27: 17-Mar-26 12:01 AM EDT | J27: 17-Mar-26 11:59 PM CDT | K27: Dry Van | L27: 111 lb | M27: LTL | N27: ESTES EXPRESS LINES | O27: EXLA | P27: 147.1 | Q27: 862312786 | R27: 16-Mar-26 11:46 AM EDT | S27: 44 in x 44 in x 42 in cabinet - accessories | T27: 65 | U27: 1 ea | V27: 17-Mar-26 1:41 PM EDT | W27: =IF(I27="","",DATE(2000+MID(I27,8,2),MATCH(MID(I27,4,3),{"Jan","Feb","Mar","Apr","May","Jun","Jul","Aug","Sep","Oct","Nov","Dec"},0),1)) -> 46082 | X27: =IF(L27="","",SUBSTITUTE(SUBSTITUTE(L27,",","")," lb",""))*1 -> 111 | Y27: =IF(H27="","",SUBSTITUTE(SUBSTITUTE(H27,",","")," mi",""))*1 -> 329
A28: Covered | B28: KITCHEN KOMPACT INC | C28: JEFFERSONVILLE | D28: IN | E28: BLUELINX CHICAGO | F28: UNIVERSITY PARK | G28: IL | H28: 274 mi | I28: 09-Feb-26 12:01 AM EST | J28: 10-Feb-26 11:59 PM CST | K28: Dry Van | L28: 499 lb | M28: LTL | N28: ESTES EXPRESS LINES | O28: EXLA | P28: 189.87 | R28: 14-Jan-26 8:51 AM EST | S28: 44inx44inx83in - cabinets - palletized | T28: 65 | U28: 3 ea | W28: =IF(I28="","",DATE(2000+MID(I28,8,2),MATCH(MID(I28,4,3),{"Jan","Feb","Mar","Apr","May","Jun","Jul","Aug","Sep","Oct","Nov","Dec"},0),1)) -> 46054 | X28: =IF(L28="","",SUBSTITUTE(SUBSTITUTE(L28,",","")," lb",""))*1 -> 499 | Y28: =IF(H28="","",SUBSTITUTE(SUBSTITUTE(H28,",","")," mi",""))*1 -> 274
A29: Covered | B29: KITCHEN KOMPACT INC | C29: JEFFERSONVILLE | D29: IN | E29: PRO DESK HOME DEPOT #2001 | F29: MERRILLVILLE | G29: IN | H29: 255 mi | I29: 09-Feb-26 12:01 AM EST | J29: 10-Feb-26 11:59 PM CST | K29: Dry Van | L29: 825 lb | M29: LTL | N29: ESTES EXPRESS LINES | O29: EXLA | P29: 209.19 | Q29: 862251504 | R29: 06-Feb-26 10:51 AM EST | S29: 44inx44inx83in - cabinets - palletized | T29: 65 | U29: 6 ea | V29: 09-Feb-26 3:45 PM EST | W29: =IF(I29="","",DATE(2000+MID(I29,8,2),MATCH(MID(I29,4,3),{"Jan","Feb","Mar","Apr","May","Jun","Jul","Aug","Sep","Oct","Nov","Dec"},0),1)) -> 46054 | X29: =IF(L29="","",SUBSTITUTE(SUBSTITUTE(L29,",","")," lb",""))*1 -> 825 | Y29: =IF(H29="","",SUBSTITUTE(SUBSTITUTE(H29,",","")," mi",""))*1 -> 255
A30: Covered | B30: BLUELINX- BROKEN ARROW | C30: BROKEN ARROW | D30: OK | E30: GRASSY CREEK, LBM #2196 SPRUCE | F30: SPRUCE PINE | G30: NC | H30: 925 mi | I30: 07-Jan-26 12:01 AM CST | J30: 07-Jan-26 11:59 PM EST | K30: Dry Van | L30: 88 lb | M30: LTL | N30: ESTES EXPRESS LINES | O30: EXLA | P30: 168.02 | Q30: 1950765757 | R30: 06-Jan-26 12:11 PM EST | S30: 48 in liners | T30: 65 | U30: 1 ea | V30: 07-Jan-26 1:04 PM CST | W30: =IF(I30="","",DATE(2000+MID(I30,8,2),MATCH(MID(I30,4,3),{"Jan","Feb","Mar","Apr","May","Jun","Jul","Aug","Sep","Oct","Nov","Dec"},0),1)) -> 46023 | X30: =IF(L30="","",SUBSTITUTE(SUBSTITUTE(L30,",","")," lb",""))*1 -> 88 | Y30: =IF(H30="","",SUBSTITUTE(SUBSTITUTE(H30,",","")," mi",""))*1 -> 925
A31: Covered | B31: Kronospan | C31: SHIPPENVILLE | D31: PA | E31: FUNDER AMERICA, INC. 50100 | F31: MOCKSVILLE | G31: NC | H31: 502 mi | I31: 24-Oct-25 12:01 AM EDT | J31: 24-Oct-25 11:59 PM EDT | K31: Dry Van | L31: 2,600 lb | M31: LTL | N31: ESTES EXPRESS LINES | O31: EXLA | P31: 338.92 | Q31: 553084931 | R31: 23-Oct-25 1:16 PM EDT | S31: 48 in x 96 in board | T31: 65 | U31: 1 ea | V31: 24-Oct-25 12:33 PM EDT | W31: =IF(I31="","",DATE(2000+MID(I31,8,2),MATCH(MID(I31,4,3),{"Jan","Feb","Mar","Apr","May","Jun","Jul","Aug","Sep","Oct","Nov","Dec"},0),1)) -> 45931 | X31: =IF(L31="","",SUBSTITUTE(SUBSTITUTE(L31,",","")," lb",""))*1 -> 2600 | Y31: =IF(H31="","",SUBSTITUTE(SUBSTITUTE(H31,",","")," mi",""))*1 -> 502
A32: Covered | B32: BlueLinx Corporation | C32: Elkhart | D32: IN | E32: SATELLITE SHELTERS INC | F32: HAMILTON | G32: OH | H32: 196 mi | I32: 02-Mar-26 12:01 AM EST | J32: 02-Mar-26 11:59 PM EST | K32: Dry Van | L32: 1,050 lb | M32: LTL | N32: ESTES EXPRESS LINES | O32: EXLA | P32: 183.52 | Q32: 1271509442 | R32: 27-Feb-26 1:56 PM EST | S32: 48 in x 96 in board | T32: 65 | U32: 1 ea | V32: 02-Mar-26 12:31 PM EST | W32: =IF(I32="","",DATE(2000+MID(I32,8,2),MATCH(MID(I32,4,3),{"Jan","Feb","Mar","Apr","May","Jun","Jul","Aug","Sep","Oct","Nov","Dec"},0),1)) -> 46082 | X32: =IF(L32="","",SUBSTITUTE(SUBSTITUTE(L32,",","")," lb",""))*1 -> 1050 | Y32: =IF(H32="","",SUBSTITUTE(SUBSTITUTE(H32,",","")," mi",""))*1 -> 196
A33: Covered | B33: BLUELINX - FORT WORTH | C33: FORT WORTH | D33: TX | E33: YODERS BLDG SPLY, LMC #211300 | F33: FAIR PLAY | G33: SC | H33: 914 mi | I33: 20-Jan-26 8:00 AM CST | J33: 21-Jan-26 5:00 PM EST | K33: Dry Van | L33: 5,100 lb | M33: LTL | N33: Southeastern Freight | O33: SEFL | P33: 659.75 | Q33: 464092850 | R33: 19-Jan-26 9:01 AM EST | S33: 48 in x 96 in board and 4x4 pallet tape and accessories | T33: 65 | U33: 2 ea | V33: 20-Jan-26 8:00 AM CST | W33: =IF(I33="","",DATE(2000+MID(I33,8,2),MATCH(MID(I33,4,3),{"Jan","Feb","Mar","Apr","May","Jun","Jul","Aug","Sep","Oct","Nov","Dec"},0),1)) -> 46023 | X33: =IF(L33="","",SUBSTITUTE(SUBSTITUTE(L33,",","")," lb",""))*1 -> 5100 | Y33: =IF(H33="","",SUBSTITUTE(SUBSTITUTE(H33,",","")," mi",""))*1 -> 914
A34: Covered | B34: CELLOFOAM NA | C34: WINCHESTER | D34: VA | E34: VICTORY TRAILERS - ROCKY MOUNT | F34: ROCK MOUNT | G34: VA | H34: 199 mi | I34: 29-Jan-26 12:01 AM EST | J34: 30-Jan-26 11:59 PM EST | K34: Dry Van | L34: 234.96 lb | M34: LTL | N34: ESTES EXPRESS LINES | O34: EXLA | P34: 223.57 | Q34: 51812853 | R34: 28-Jan-26 10:51 AM EST | S34: 48 in x 96 in board w/insulation | T34: 250 | U34: 4 ea | V34: 29-Jan-26 3:40 PM EST | W34: =IF(I34="","",DATE(2000+MID(I34,8,2),MATCH(MID(I34,4,3),{"Jan","Feb","Mar","Apr","May","Jun","Jul","Aug","Sep","Oct","Nov","Dec"},0),1)) -> 46023 | X34: =IF(L34="","",SUBSTITUTE(SUBSTITUTE(L34,",","")," lb",""))*1 -> 234.96 | Y34: =IF(H34="","",SUBSTITUTE(SUBSTITUTE(H34,",","")," mi",""))*1 -> 199
A35: Covered | B35: BLUELINX - LAWRENCEVILLE | C35: LAWRENCEVILLE | D35: GA | E35: Mike Fischer - warehouse | F35: Mooresville | G35: NC | H35: 237 mi | I35: 14-Nov-25 8:00 AM EST | J35: 17-Nov-25 5:00 PM EST | K35: Dry Van | L35: 400 lb | M35: LTL | N35: Southeastern Freight | O35: SEFL | P35: 206.4 | R35: 13-Nov-25 9:55 AM EST | S35: 48 in x 96 in Plywood - palletized | T35: 65 | U35: 1 ea | W35: =IF(I35="","",DATE(2000+MID(I35,8,2),MATCH(MID(I35,4,3),{"Jan","Feb","Mar","Apr","May","Jun","Jul","Aug","Sep","Oct","Nov","Dec"},0),1)) -> 45962 | X35: =IF(L35="","",SUBSTITUTE(SUBSTITUTE(L35,",","")," lb",""))*1 -> 400 | Y35: =IF(H35="","",SUBSTITUTE(SUBSTITUTE(H35,",","")," mi",""))*1 -> 237
A36: Covered | B36: CELLOFOAM NA | C36: WINCHESTER | D36: VA | E36: VICTORY TRAILERS - ROCKY MOUNT | F36: ROCK MOUNT | G36: VA | H36: 199 mi | I36: 02-Dec-25 12:01 AM EST | J36: 04-Dec-25 11:59 PM EST | K36: Dry Van | L36: 234.96 lb | M36: LTL | N36: ESTES EXPRESS LINES | O36: EXLA | P36: 207.8 | Q36: 51811439 | R36: 01-Dec-25 1:01 PM EST | S36: 48x units insulation | T36: 250 | U36: 4 ea | V36: 03-Dec-25 2:40 PM EST | W36: =IF(I36="","",DATE(2000+MID(I36,8,2),MATCH(MID(I36,4,3),{"Jan","Feb","Mar","Apr","May","Jun","Jul","Aug","Sep","Oct","Nov","Dec"},0),1)) -> 45992 | X36: =IF(L36="","",SUBSTITUTE(SUBSTITUTE(L36,",","")," lb",""))*1 -> 234.96 | Y36: =IF(H36="","",SUBSTITUTE(SUBSTITUTE(H36,",","")," mi",""))*1 -> 199
A37: Covered | B37: BLUELINX RALEIGH | C37: BUTNER | D37: NC | E37: BLUELINX CHARLESTON | F37: CHARLESTON | G37: SC | H37: 291 mi | I37: 11-Mar-26 12:01 AM EDT | J37: 11-Mar-26 11:59 PM EDT | K37: Dry Van | L37: 3,118.71 lb | M37: LTL | N37: ESTES EXPRESS LINES | O37: EXLA | P37: 352.12 | Q37: 112810844 | R37: 10-Mar-26 5:06 PM EDT | S37: 49 in x 97 in board | T37: 65 | U37: 1 ea | V37: 11-Mar-26 4:00 PM EDT | W37: =IF(I37="","",DATE(2000+MID(I37,8,2),MATCH(MID(I37,4,3),{"Jan","Feb","Mar","Apr","May","Jun","Jul","Aug","Sep","Oct","Nov","Dec"},0),1)) -> 46082 | X37: =IF(L37="","",SUBSTITUTE(SUBSTITUTE(L37,",","")," lb",""))*1 -> 3118.71 | Y37: =IF(H37="","",SUBSTITUTE(SUBSTITUTE(H37,",","")," mi",""))*1 -> 291
A38: Covered | B38: BLUELINX EL PASO | C38: EL PASO | D38: TX | E38: LOWES #1429 BEAUMONT CA FDC | F38: BEAUMONT | G38: CA | H38: 695 mi | I38: 03-Mar-26 12:01 AM MST | J38: 05-Mar-26 11:59 PM PST | K38: Dry Van | L38: 3,408.34 lb | M38: LTL | N38: ESTES EXPRESS LINES | O38: EXLA | P38: 869.64 | Q38: 2301151821 | R38: 02-Mar-26 1:36 PM EST | S38: 4ft and 10ft units - home framing accessories | T38: 65 | U38: 5 ea | V38: 03-Mar-26 12:27 PM MST | W38: =IF(I38="","",DATE(2000+MID(I38,8,2),MATCH(MID(I38,4,3),{"Jan","Feb","Mar","Apr","May","Jun","Jul","Aug","Sep","Oct","Nov","Dec"},0),1)) -> 46082 | X38: =IF(L38="","",SUBSTITUTE(SUBSTITUTE(L38,",","")," lb",""))*1 -> 3408.34 | Y38: =IF(H38="","",SUBSTITUTE(SUBSTITUTE(H38,",","")," mi",""))*1 -> 695
A39: Covered | B39: CEDAR CREEK KSC | C39: KANSAS CITY | D39: MO | E39: BLUELINX MEM | F39: MEMPHIS | G39: TN | H39: 469 mi | I39: 04-Mar-26 12:01 AM CST | J39: 06-Mar-26 11:59 PM CST | K39: Dry Van | L39: 1,464 lb | M39: LTL | N39: ESTES EXPRESS LINES | O39: EXLA | P39: 354.58 | R39: 03-Mar-26 8:51 AM EST | S39: 4ft Greenbar - Fiberbar- palletized | T39: 65 | U39: 1 ea | W39: =IF(I39="","",DATE(2000+MID(I39,8,2),MATCH(MID(I39,4,3),{"Jan","Feb","Mar","Apr","May","Jun","Jul","Aug","Sep","Oct","Nov","Dec"},0),1)) -> 46082 | X39: =IF(L39="","",SUBSTITUTE(SUBSTITUTE(L39,",","")," lb",""))*1 -> 1464 | Y39: =IF(H39="","",SUBSTITUTE(SUBSTITUTE(H39,",","")," mi",""))*1 -> 469
A40: Covered | B40: BlueLinx Corporation | C40: Elkhart | D40: IN | E40: CHAMPION HOME BLDRS-WEISER | F40: WEISER | G40: ID | H40: 1,841 mi | I40: 24-Feb-26 12:01 AM EST | J40: 24-Feb-26 11:59 PM MST | K40: Dry Van | L40: 4,725 lb | M40: LTL | N40: ESTES EXPRESS LINES | O40: EXLA | P40: 1344.6 | Q40: 1271509380 | R40: 23-Feb-26 9:01 AM EST | S40: 4ft x 4ft x 92in - Door jambs and accessories | T40: 125 | U40: 7 ea | V40: 24-Feb-26 12:55 PM EST | W40: =IF(I40="","",DATE(2000+MID(I40,8,2),MATCH(MID(I40,4,3),{"Jan","Feb","Mar","Apr","May","Jun","Jul","Aug","Sep","Oct","Nov","Dec"},0),1)) -> 46054 | X40: =IF(L40="","",SUBSTITUTE(SUBSTITUTE(L40,",","")," lb",""))*1 -> 4725 | Y40: =IF(H40="","",SUBSTITUTE(SUBSTITUTE(H40,",","")," mi",""))*1 -> 1841
...

Sheet LTL Trending Analysis
A1: LTL Shipment Trending Analysis
A2: Data Period: October 2025 – March 2026
A4: Monthly Shipment Summary
A5: Month | B5: Shipment Count | C5: Total Spend | D5: Avg Cost/Shipment | E5: Total Weight (lbs) | F5: Avg Weight/Shipment | G5: Total Distance (mi) | H5: Avg Distance/Shipment | I5: Avg Cost per lb | J5: Avg Cost per Mile | L5: Month | M5: Total Spend | N5: Avg Cost/Shipment | O5: Avg Weight/Shipment | Q5: Month | R5: Avg Cost/Shipment
A6: Oct-25 | B6: =COUNTIF('SCI_Report#BL68LX#jwade#25-MAR-'!W:W,DATE(2025,10,1)) -> 45 | C6: =SUMIF('SCI_Report#BL68LX#jwade#25-MAR-'!W:W,DATE(2025,10,1),'SCI_Report#BL68LX#jwade#25-MAR-'!P:P) -> 11138.72 | D6: =IF(B6=0,"-",C6/B6) -> 247.52711 | E6: =SUMIF('SCI_Report#BL68LX#jwade#25-MAR-'!W:W,DATE(2025,10,1),'SCI_Report#BL68LX#jwade#25-MAR-'!X:X) -> 92475.37 | F6: =IF(B6=0,"-",E6/B6) -> 2055.0082 | G6: =SUMIF('SCI_Report#BL68LX#jwade#25-MAR-'!W:W,DATE(2025,10,1),'SCI_Report#BL68LX#jwade#25-MAR-'!Y:Y) -> 19198 | H6: =IF(B6=0,"-",G6/B6) -> 426.62222 | I6: =IF(E6=0,"-",C6/E6) -> 0.12045067 | J6: =IF(G6=0,"-",C6/G6) -> 0.5802021 | L6: 46320 | M6: =C6 -> 11138.72 | N6: =D6 -> 247.52711 | O6: =F6 -> 2055.0082 | Q6: 46320 | R6: =D6 -> 247.52711
A7: Nov-25 | B7: =COUNTIF('SCI_Report#BL68LX#jwade#25-MAR-'!W:W,DATE(2025,11,1)) -> 35 | C7: =SUMIF('SCI_Report#BL68LX#jwade#25-MAR-'!W:W,DATE(2025,11,1),'SCI_Report#BL68LX#jwade#25-MAR-'!P:P) -> 13021.51 | D7: =IF(B7=0,"-",C7/B7) -> 372.04314 | E7: =SUMIF('SCI_Report#BL68LX#jwade#25-MAR-'!W:W,DATE(2025,11,1),'SCI_Report#BL68LX#jwade#25-MAR-'!X:X) -> 87192.17 | F7: =IF(B7=0,"-",E7/B7) -> 2491.2049 | G7: =SUMIF('SCI_Report#BL68LX#jwade#25-MAR-'!W:W,DATE(2025,11,1),'SCI_Report#BL68LX#jwade#25-MAR-'!Y:Y) -> 16181 | H7: =IF(B7=0,"-",G7/B7) -> 462.31429 | I7: =IF(E7=0,"-",C7/E7) -> 0.14934265 | J7: =IF(G7=0,"-",C7/G7) -> 0.80474075 | L7: 46351 | M7: =C7 -> 13021.51 | N7: =D7 -> 372.04314 | O7: =F7 -> 2491.2049 | Q7: 46351 | R7: =D7 -> 372.04314
A8: Dec-25 | B8: =COUNTIF('SCI_Report#BL68LX#jwade#25-MAR-'!W:W,DATE(2025,12,1)) -> 30 | C8: =SUMIF('SCI_Report#BL68LX#jwade#25-MAR-'!W:W,DATE(2025,12,1),'SCI_Report#BL68LX#jwade#25-MAR-'!P:P) -> 6542.96 | D8: =IF(B8=0,"-",C8/B8) -> 218.09867 | E8: =SUMIF('SCI_Report#BL68LX#jwade#25-MAR-'!W:W,DATE(2025,12,1),'SCI_Report#BL68LX#jwade#25-MAR-'!X:X) -> 35541.62 | F8: =IF(B8=0,"-",E8/B8) -> 1184.7207 | G8: =SUMIF('SCI_Report#BL68LX#jwade#25-MAR-'!W:W,DATE(2025,12,1),'SCI_Report#BL68LX#jwade#25-MAR-'!Y:Y) -> 9352 | H8: =IF(B8=0,"-",G8/B8) -> 311.73333 | I8: =IF(E8=0,"-",C8/E8) -> 0.1840929 | J8: =IF(G8=0,"-",C8/G8) -> 0.69963216 | L8: 46381 | M8: =C8 -> 6542.96 | N8: =D8 -> 218.09867 | O8: =F8 -> 1184.7207 | Q8: 46381 | R8: =D8 -> 218.09867
A9: Jan-26 | B9: =COUNTIF('SCI_Report#BL68LX#jwade#25-MAR-'!W:W,DATE(2026,1,1)) -> 39 | C9: =SUMIF('SCI_Report#BL68LX#jwade#25-MAR-'!W:W,DATE(2026,1,1),'SCI_Report#BL68LX#jwade#25-MAR-'!P:P) -> 13432.45 | D9: =IF(B9=0,"-",C9/B9) -> 344.42179 | E9: =SUMIF('SCI_Report#BL68LX#jwade#25-MAR-'!W:W,DATE(2026,1,1),'SCI_Report#BL68LX#jwade#25-MAR-'!X:X) -> 90921.37 | F9: =IF(B9=0,"-",E9/B9) -> 2331.3172 | G9: =SUMIF('SCI_Report#BL68LX#jwade#25-MAR-'!W:W,DATE(2026,1,1),'SCI_Report#BL68LX#jwade#25-MAR-'!Y:Y) -> 22803 | H9: =IF(B9=0,"-",G9/B9) -> 584.69231 | I9: =IF(E9=0,"-",C9/E9) -> 0.147737 | J9: =IF(G9=0,"-",C9/G9) -> 0.58906504 | L9: 46048 | M9: =C9 -> 13432.45 | N9: =D9 -> 344.42179 | O9: =F9 -> 2331.3172 | Q9: 46048 | R9: =D9 -> 344.42179
A10: Feb-26 | B10: =COUNTIF('SCI_Report#BL68LX#jwade#25-MAR-'!W:W,DATE(2026,2,1)) -> 37 | C10: =SUMIF('SCI_Report#BL68LX#jwade#25-MAR-'!W:W,DATE(2026,2,1),'SCI_Report#BL68LX#jwade#25-MAR-'!P:P) -> 12531.78 | D10: =IF(B10=0,"-",C10/B10) -> 338.69676 | E10: =SUMIF('SCI_Report#BL68LX#jwade#25-MAR-'!W:W,DATE(2026,2,1),'SCI_Report#BL68LX#jwade#25-MAR-'!X:X) -> 54113.61 | F10: =IF(B10=0,"-",E10/B10) -> 1462.53 | G10: =SUMIF('SCI_Report#BL68LX#jwade#25-MAR-'!W:W,DATE(2026,2,1),'SCI_Report#BL68LX#jwade#25-MAR-'!Y:Y) -> 24433 | H10: =IF(B10=0,"-",G10/B10) -> 660.35135 | I10: =IF(E10=0,"-",C10/E10) -> 0.23158278 | J10: =IF(G10=0,"-",C10/G10) -> 0.51290386 | L10: 46079 | M10: =C10 -> 12531.78 | N10: =D10 -> 338.69676 | O10: =F10 -> 1462.53 | Q10: 46079 | R10: =D10 -> 338.69676
A11: Mar-26 | B11: =COUNTIF('SCI_Report#BL68LX#jwade#25-MAR-'!W:W,DATE(2026,3,1)) -> 44 | C11: =SUMIF('SCI_Report#BL68LX#jwade#25-MAR-'!W:W,DATE(2026,3,1),'SCI_Report#BL68LX#jwade#25-MAR-'!P:P) -> 17742.69 | D11: =IF(B11=0,"-",C11/B11) -> 403.24295 | E11: =SUMIF('SCI_Report#BL68LX#jwade#25-MAR-'!W:W,DATE(2026,3,1),'SCI_Report#BL68LX#jwade#25-MAR-'!X:X) -> 86906.87 | F11: =IF(B11=0,"-",E11/B11) -> 1975.1561 | G11: =SUMIF('SCI_Report#BL68LX#jwade#25-MAR-'!W:W,DATE(2026,3,1),'SCI_Report#BL68LX#jwade#25-MAR-'!Y:Y) -> 27261 | H11: =IF(B11=0,"-",G11/B11) -> 619.56818 | I11: =IF(E11=0,"-",C11/E11) -> 0.20415751 | J11: =IF(G11=0,"-",C11/G11) -> 0.65084516 | L11: 46107 | M11: =C11 -> 17742.69 | N11: =D11 -> 403.24295 | O11: =F11 -> 1975.1561 | Q11: 46107 | R11: =D11 -> 403.24295
A12: Total / Avg | B12: =SUM(B6:B11) -> 230 | C12: =SUM(C6:C11) -> 74410.11 | D12: =IF(B12=0,"-",C12/B12) -> 323.52222 | E12: =SUM(E6:E11) -> 447151.01 | F12: =IF(B12=0,"-",E12/B12) -> 1944.1348 | G12: =SUM(G6:G11) -> 119228 | H12: =IF(B12=0,"-",G12/B12) -> 518.38261 | I12: =IF(E12=0,"-",C12/E12) -> 0.16640935 | J12: =IF(G12=0,"-",C12/G12) -> 0.62409929
Q13: Month | R13: Avg Weight (lbs)
A14: Month-over-Month Change | Q14: 46320 | R14: =F6 -> 2055.0082
A15: Month | B15: Shipment Δ | C15: Shipment Δ % | D15: Spend Δ | E15: Spend Δ % | F15: Avg Cost Δ % | G15: Weight Δ % | Q15: 46351 | R15: =F7 -> 2491.2049
A16: Nov-25 | B16: =B7-B6 -> -10 | C16: =IF(B6=0,"-",(B7-B6)/B6) -> -0.22222222 | D16: =C7-C6 -> 1882.79 | E16: =IF(C6=0,"-",(C7-C6)/C6) -> 0.16903109 | F16: =IF(D6=0,"-",(D7-D6)/D6) -> 0.50303997 | G16: =IF(E6=0,"-",(E7-E6)/E6) -> -0.057130888 | Q16: 46381 | R16: =F8 -> 1184.7207
A17: Dec-25 | B17: =B8-B7 -> -5 | C17: =IF(B7=0,"-",(B8-B7)/B7) -> -0.14285714 | D17: =C8-C7 -> -6478.55 | E17: =IF(C7=0,"-",(C8-C7)/C7) -> -0.49752678 | F17: =IF(D7=0,"-",(D8-D7)/D7) -> -0.41378125 | G17: =IF(E7=0,"-",(E8-E7)/E7) -> -0.59237601 | Q17: 46048 | R17: =F9 -> 2331.3172
A18: Jan-26 | B18: =B9-B8 -> 9 | C18: =IF(B8=0,"-",(B9-B8)/B8) -> 0.3 | D18: =C9-C8 -> 6889.49 | E18: =IF(C8=0,"-",(C9-C8)/C8) -> 1.0529623 | F18: =IF(D8=0,"-",(D9-D8)/D8) -> 0.57920174 | G18: =IF(E8=0,"-",(E9-E8)/E8) -> 1.5581662 | Q18: 46079 | R18: =F10 -> 1462.53
A19: Feb-26 | B19: =B10-B9 -> -2 | C19: =IF(B9=0,"-",(B10-B9)/B9) -> -0.051282051 | D19: =C10-C9 -> -900.67 | E19: =IF(C9=0,"-",(C10-C9)/C9) -> -0.067051804 | F19: =IF(D9=0,"-",(D10-D9)/D9) -> -0.016622171 | G19: =IF(E9=0,"-",(E10-E9)/E9) -> -0.40483068 | Q19: 46107 | R19: =F11 -> 1975.1561
A20: Mar-26 | B20: =B11-B10 -> 7 | C20: =IF(B10=0,"-",(B11-B10)/B10) -> 0.18918919 | D20: =C11-C10 -> 5210.91 | E20: =IF(C10=0,"-",(C11-C10)/C10) -> 0.41581563 | F20: =IF(D10=0,"-",(D11-D10)/D10) -> 0.19057223 | G20: =IF(E10=0,"-",(E11-E10)/E10) -> 0.60600762
A22: Carrier Breakdown
A23: Carrier | B23: Shipment Count | C23: % of Total | D23: Total Spend | E23: Avg Cost/Shipment
A24: ESTES EXPRESS LINES | B24: =COUNTIF('SCI_Report#BL68LX#jwade#25-MAR-'!N:N,"ESTES EXPRESS LINES") -> 184 | C24: =B24/B$12 -> 0.8 | D24: =SUMIF('SCI_Report#BL68LX#jwade#25-MAR-'!N:N,"ESTES EXPRESS LINES",'SCI_Report#BL68LX#jwade#25-MAR-'!P:P) -> 63832.01 | E24: =IF(B24=0,"-",D24/B24) -> 346.9131
A25: Southeastern Freight | B25: =COUNTIF('SCI_Report#BL68LX#jwade#25-MAR-'!N:N,"Southeastern Freight") -> 46 | C25: =B25/B$12 -> 0.2 | D25: =SUMIF('SCI_Report#BL68LX#jwade#25-MAR-'!N:N,"Southeastern Freight",'SCI_Report#BL68LX#jwade#25-MAR-'!P:P) -> 10578.1 | E25: =IF(B25=0,"-",D25/B25) -> 229.9587
A26: Total | B26: =SUM(B24:B25) -> 230 | C26: =SUM(C24:C25) -> 1 | D26: =SUM(D24:D25) -> 74410.11 | E26: =IF(B26=0,"-",D26/B26) -> 323.52222
A28: Top 15 Shipping Lanes (by Volume)
A29: Rank | B29: Origin State | C29: Dest State | D29: Shipment Count | E29: Total Spend | F29: Avg Cost/Shipment
A30: 1 | B30: FL | C30: FL | D30: =COUNTIFS('SCI_Report#BL68LX#jwade#25-MAR-'!D:D,"FL",'SCI_Report#BL68LX#jwade#25-MAR-'!G:G,"FL") -> 18 | E30: =SUMIFS('SCI_Report#BL68LX#jwade#25-MAR-'!P:P,'SCI_Report#BL68LX#jwade#25-MAR-'!D:D,"FL",'SCI_Report#BL68LX#jwade#25-MAR-'!G:G,"FL") -> 3252.61 | F30: =IF(D30=0,"-",E30/D30) -> 180.70056
A31: 2 | B31: GA | C31: NC | D31: =COUNTIFS('SCI_Report#BL68LX#jwade#25-MAR-'!D:D,"GA",'SCI_Report#BL68LX#jwade#25-MAR-'!G:G,"NC") -> 13 | E31: =SUMIFS('SCI_Report#BL68LX#jwade#25-MAR-'!P:P,'SCI_Report#BL68LX#jwade#25-MAR-'!D:D,"GA",'SCI_Report#BL68LX#jwade#25-MAR-'!G:G,"NC") -> 1937.05 | F31: =IF(D31=0,"-",E31/D31) -> 149.00385
A32: 3 | B32: TX | C32: TX | D32: =COUNTIFS('SCI_Report#BL68LX#jwade#25-MAR-'!D:D,"TX",'SCI_Report#BL68LX#jwade#25-MAR-'!G:G,"TX") -> 10 | E32: =SUMIFS('SCI_Report#BL68LX#jwade#25-MAR-'!P:P,'SCI_Report#BL68LX#jwade#25-MAR-'!D:D,"TX",'SCI_Report#BL68LX#jwade#25-MAR-'!G:G,"TX") -> 1523.23 | F32: =IF(D32=0,"-",E32/D32) -> 152.323
A33: 4 | B33: TN | C33: NC | D33: =COUNTIFS('SCI_Report#BL68LX#jwade#25-MAR-'!D:D,"TN",'SCI_Report#BL68LX#jwade#25-MAR-'!G:G,"NC") -> 9 | E33: =SUMIFS('SCI_Report#BL68LX#jwade#25-MAR-'!P:P,'SCI_Report#BL68LX#jwade#25-MAR-'!D:D,"TN",'SCI_Report#BL68LX#jwade#25-MAR-'!G:G,"NC") -> 2429 | F33: =IF(D33=0,"-",E33/D33) -> 269.88889
A34: 5 | B34: IN | C34: IL | D34: =COUNTIFS('SCI_Report#BL68LX#jwade#25-MAR-'!D:D,"IN",'SCI_Report#BL68LX#jwade#25-MAR-'!G:G,"IL") -> 8 | E34: =SUMIFS('SCI_Report#BL68LX#jwade#25-MAR-'!P:P,'SCI_Report#BL68LX#jwade#25-MAR-'!D:D,"IN",'SCI_Report#BL68LX#jwade#25-MAR-'!G:G,"IL") -> 1367.9 | F34: =IF(D34=0,"-",E34/D34) -> 170.9875
A35: 6 | B35: IN | C35: PA | D35: =COUNTIFS('SCI_Report#BL68LX#jwade#25-MAR-'!D:D,"IN",'SCI_Report#BL68LX#jwade#25-MAR-'!G:G,"PA") -> 6 | E35: =SUMIFS('SCI_Report#BL68LX#jwade#25-MAR-'!P:P,'SCI_Report#BL68LX#jwade#25-MAR-'!D:D,"IN",'SCI_Report#BL68LX#jwade#25-MAR-'!G:G,"PA") -> 2418.36 | F35: =IF(D35=0,"-",E35/D35) -> 403.06
A36: 7 | B36: PA | C36: IL | D36: =COUNTIFS('SCI_Report#BL68LX#jwade#25-MAR-'!D:D,"PA",'SCI_Report#BL68LX#jwade#25-MAR-'!G:G,"IL") -> 5 | E36: =SUMIFS('SCI_Report#BL68LX#jwade#25-MAR-'!P:P,'SCI_Report#BL68LX#jwade#25-MAR-'!D:D,"PA",'SCI_Report#BL68LX#jwade#25-MAR-'!G:G,"IL") -> 2061.47 | F36: =IF(D36=0,"-",E36/D36) -> 412.294
A37: 8 | B37: PA | C37: NJ | D37: =COUNTIFS('SCI_Report#BL68LX#jwade#25-MAR-'!D:D,"PA",'SCI_Report#BL68LX#jwade#25-MAR-'!G:G,"NJ") -> 5 | E37: =SUMIFS('SCI_Report#BL68LX#jwade#25-MAR-'!P:P,'SCI_Report#BL68LX#jwade#25-MAR-'!D:D,"PA",'SCI_Report#BL68LX#jwade#25-MAR-'!G:G,"NJ") -> 2200.75 | F37: =IF(D37=0,"-",E37/D37) -> 440.15
A38: 9 | B38: IN | C38: CA | D38: =COUNTIFS('SCI_Report#BL68LX#jwade#25-MAR-'!D:D,"IN",'SCI_Report#BL68LX#jwade#25-MAR-'!G:G,"CA") -> 4 | E38: =SUMIFS('SCI_Report#BL68LX#jwade#25-MAR-'!P:P,'SCI_Report#BL68LX#jwade#25-MAR-'!D:D,"IN",'SCI_Report#BL68LX#jwade#25-MAR-'!G:G,"CA") -> 3476.36 | F38: =IF(D38=0,"-",E38/D38) -> 869.09
A39: 10 | B39: GA | C39: TX | D39: =COUNTIFS('SCI_Report#BL68LX#jwade#25-MAR-'!D:D,"GA",'SCI_Report#BL68LX#jwade#25-MAR-'!G:G,"TX") -> 4 | E39: =SUMIFS('SCI_Report#BL68LX#jwade#25-MAR-'!P:P,'SCI_Report#BL68LX#jwade#25-MAR-'!D:D,"GA",'SCI_Report#BL68LX#jwade#25-MAR-'!G:G,"TX") -> 2683.44 | F39: =IF(D39=0,"-",E39/D39) -> 670.86
A40: 11 | B40: SC | C40: NC | D40: =COUNTIFS('SCI_Report#BL68LX#jwade#25-MAR-'!D:D,"SC",'SCI_Report#BL68LX#jwade#25-MAR-'!G:G,"NC") -> 4 | E40: =SUMIFS('SCI_Report#BL68LX#jwade#25-MAR-'!P:P,'SCI_Report#BL68LX#jwade#25-MAR-'!D:D,"SC",'SCI_Report#BL68LX#jwade#25-MAR-'!G:G,"NC") -> 521.33 | F40: =IF(D40=0,"-",E40/D40) -> 130.3325
A41: 12 | B41: NC | C41: FL | D41: =COUNTIFS('SCI_Report#BL68LX#jwade#25-MAR-'!D:D,"NC",'SCI_Report#BL68LX#jwade#25-MAR-'!G:G,"FL") -> 4 | E41: =SUMIFS('SCI_Report#BL68LX#jwade#25-MAR-'!P:P,'SCI_Report#BL68LX#jwade#25-MAR-'!D:D,"NC",'SCI_Report#BL68LX#jwade#25-MAR-'!G:G,"FL") -> 626.02 | F41: =IF(D41=0,"-",E41/D41) -> 156.505
A42: 13 | B42: IN | C42: OH | D42: =COUNTIFS('SCI_Report#BL68LX#jwade#25-MAR-'!D:D,"IN",'SCI_Report#BL68LX#jwade#25-MAR-'!G:G,"OH") -> 3 | E42: =SUMIFS('SCI_Report#BL68LX#jwade#25-MAR-'!P:P,'SCI_Report#BL68LX#jwade#25-MAR-'!D:D,"IN",'SCI_Report#BL68LX#jwade#25-MAR-'!G:G,"OH") -> 963.19 | F42: =IF(D42=0,"-",E42/D42) -> 321.06333
A43: 14 | B43: IN | C43: MN | D43: =COUNTIFS('SCI_Report#BL68LX#jwade#25-MAR-'!D:D,"IN",'SCI_Report#BL68LX#jwade#25-MAR-'!G:G,"MN") -> 3 | E43: =SUMIFS('SCI_Report#BL68LX#jwade#25-MAR-'!P:P,'SCI_Report#BL68LX#jwade#25-MAR-'!D:D,"IN",'SCI_Report#BL68LX#jwade#25-MAR-'!G:G,"MN") -> 2427.77 | F43: =IF(D43=0,"-",E43/D43) -> 809.25667
...
